<?xml version='1.0' encoding='utf-8'?>
<robot name="RH56F1">
  <material name="dark">
    <color rgba="0.2 0.2 0.2 1" />
  </material>
  <material name="white">
    <color rgba="0.7 0.7 0.7 1" />
  </material>
  <material name="green_ball">
    <color rgba="0 1 0 1" />
  </material>
  <material name="red_ball">
    <color rgba="1 0 0 1" />
  </material>

  <mujoco>
    <compiler meshdir="meshes" discardvisual="false" />
  </mujoco>


  <link name="pelvis">
    <inertial>
      <origin xyz="0 0 -0.07605" rpy="0 0 0" />
      <mass value="3.813" />
      <inertia ixx="0.010549" ixy="0" ixz="2.1E-06" iyy="0.0093089" iyz="0" izz="0.0079184" />
    </inertial>
    <visual>
      <origin xyz="0 0 0" rpy="0 0 0" />
      <geometry>
        <mesh filename="meshes/pelvis.STL" />
      </geometry>
      <material name="dark" />
    </visual>
  </link>
  <link name="pelvis_contour_link">
    <inertial>
      <origin xyz="0 0 0" rpy="0 0 0" />
      <mass value="0.001" />
      <inertia ixx="1e-7" ixy="0" ixz="0" iyy="1e-7" iyz="0" izz="1e-7" />
    </inertial>
    <visual>
      <origin xyz="0 0 0" rpy="0 0 0" />
      <geometry>
        <mesh filename="meshes/pelvis_contour_link.STL" />
      </geometry>
      <material name="white">
        <color rgba="0.7 0.7 0.7 1" />
      </material>
    </visual>
    <collision>
      <origin xyz="0 0 0" rpy="0 0 0" />
      <geometry>
        <mesh filename="meshes/pelvis_contour_link.STL" />
      </geometry>
    </collision>
  </link>
  <joint name="pelvis_contour_joint" type="fixed">
    <parent link="pelvis" />
    <child link="pelvis_contour_link" />
  </joint>


  <link name="left_hip_pitch_link">
    <inertial>
      <origin xyz="0.002741 0.047791 -0.02606" rpy="0 0 0" />
      <mass value="1.35" />
      <inertia ixx="0.001811" ixy="3.68E-05" ixz="-3.44E-05" iyy="0.0014193" iyz="0.000171" izz="0.0012812" />
    </inertial>
    <visual>
      <origin xyz="0 0 0" rpy="0 0 0" />
      <geometry>
        <mesh filename="meshes/left_hip_pitch_link.STL" />
      </geometry>
      <material name="dark" />
    </visual>
    <collision>
      <origin xyz="0 0 0" rpy="0 0 0" />
      <geometry>
        <mesh filename="meshes/left_hip_pitch_link.STL" />
      </geometry>
    </collision>
  </link>
  <joint name="left_hip_pitch_joint" type="fixed">
    <origin xyz="0 0.064452 -0.1027" rpy="0 0 0" />
    <parent link="pelvis" />
    <child link="left_hip_pitch_link" />
  </joint>
  <link name="left_hip_roll_link">
    <inertial>
      <origin xyz="0.029812 -0.001045 -0.087934" rpy="0 0 0" />
      <mass value="1.52" />
      <inertia ixx="0.0023773" ixy="-3.8E-06" ixz="-0.0003908" iyy="0.0024123" iyz="1.84E-05" izz="0.0016595" />
    </inertial>
    <visual>
      <origin xyz="0 0 0" rpy="0 0 0" />
      <geometry>
        <mesh filename="meshes/left_hip_roll_link.STL" />
      </geometry>
      <material name="white">
        <color rgba="0.7 0.7 0.7 1" />
      </material>
    </visual>
    <collision>
      <origin xyz="0 0 0" rpy="0 0 0" />
      <geometry>
        <mesh filename="meshes/left_hip_roll_link.STL" />
      </geometry>
    </collision>
  </link>
  <joint name="left_hip_roll_joint" type="fixed">
    <origin xyz="0 0.052 -0.030465" rpy="0 -0.1749 0" />
    <parent link="left_hip_pitch_link" />
    <child link="left_hip_roll_link" />
  </joint>
  <link name="left_hip_yaw_link">
    <inertial>
      <origin xyz="-0.057709 -0.010981 -0.15078" rpy="0 0 0" />
      <mass value="1.702" />
      <inertia ixx="0.0057774" ixy="-0.0005411" ixz="-0.0023948" iyy="0.0076124" iyz="-0.0007072" izz="0.003149" />
    </inertial>
    <visual>
      <origin xyz="0 0 0" rpy="0 0 0" />
      <geometry>
        <mesh filename="meshes/left_hip_yaw_link.STL" />
      </geometry>
      <material name="white">
        <color rgba="0.7 0.7 0.7 1" />
      </material>
    </visual>
    <collision>
      <origin xyz="0 0 0" rpy="0 0 0" />
      <geometry>
        <mesh filename="meshes/left_hip_yaw_link.STL" />
      </geometry>
    </collision>
  </link>
  <joint name="left_hip_yaw_joint" type="fixed">
    <origin xyz="0.025001 0 -0.12412" rpy="0 0 0" />
    <parent link="left_hip_roll_link" />
    <child link="left_hip_yaw_link" />
  </joint>
  <link name="left_knee_link">
    <inertial>
      <origin xyz="0.005457 0.003964 -0.12074" rpy="0 0 0" />
      <mass value="1.932" />
      <inertia ixx="0.011329" ixy="4.82E-05" ixz="-4.49E-05" iyy="0.011277" iyz="-0.0007146" izz="0.0015168" />
    </inertial>
    <visual>
      <origin xyz="0 0 0" rpy="0 0 0" />
      <geometry>
        <mesh filename="meshes/left_knee_link.STL" />
      </geometry>
      <material name="white">
        <color rgba="0.7 0.7 0.7 1" />
      </material>
    </visual>
    <collision>
      <origin xyz="0 0 0" rpy="0 0 0" />
      <geometry>
        <mesh filename="meshes/left_knee_link.STL" />
      </geometry>
    </collision>
  </link>
  <joint name="left_knee_joint" type="fixed">
    <origin xyz="-0.078273 0.0021489 -0.17734" rpy="0 0.1749 0" />
    <parent link="left_hip_yaw_link" />
    <child link="left_knee_link" />
  </joint>
  <link name="left_ankle_pitch_link">
    <inertial>
      <origin xyz="-0.007269 0 0.011137" rpy="0 0 0" />
      <mass value="0.074" />
      <inertia ixx="8.4E-06" ixy="0" ixz="-2.9E-06" iyy="1.89E-05" iyz="0" izz="1.26E-05" />
    </inertial>
    <visual>
      <origin xyz="0 0 0" rpy="0 0 0" />
      <geometry>
        <mesh filename="meshes/left_ankle_pitch_link.STL" />
      </geometry>
      <material name="white">
        <color rgba="0.7 0.7 0.7 1" />
      </material>
    </visual>
    <collision>
      <origin xyz="0 0 0" rpy="0 0 0" />
      <geometry>
        <mesh filename="meshes/left_ankle_pitch_link.STL" />
      </geometry>
    </collision>
  </link>
  <joint name="left_ankle_pitch_joint" type="fixed">
    <origin xyz="0 -9.4445E-05 -0.30001" rpy="0 0 0" />
    <parent link="left_knee_link" />
    <child link="left_ankle_pitch_link" />
  </joint>
  <link name="left_ankle_roll_link">
    <inertial>
      <origin xyz="0.026505 0 -0.016425" rpy="0 0 0" />
      <mass value="0.608" />
      <inertia ixx="0.0002231" ixy="2E-07" ixz="8.91E-05" iyy="0.0016161" iyz="-1E-07" izz="0.0016667" />
    </inertial>
    <visual>
      <origin xyz="0 0 0" rpy="0 0 0" />
      <geometry>
        <mesh filename="meshes/left_ankle_roll_link.STL" />
      </geometry>
      <material name="dark" />
    </visual>
    <collision>
      <origin xyz="-0.05 0.025 -0.03" rpy="0 0 0" />
      <geometry>
        <sphere radius="0.005" />
      </geometry>
    </collision>
    <collision>
      <origin xyz="-0.05 -0.025 -0.03" rpy="0 0 0" />
      <geometry>
        <sphere radius="0.005" />
      </geometry>
    </collision>
    <collision>
      <origin xyz="0.12 0.03 -0.03" rpy="0 0 0" />
      <geometry>
        <sphere radius="0.005" />
      </geometry>
    </collision>
    <collision>
      <origin xyz="0.12 -0.03 -0.03" rpy="0 0 0" />
      <geometry>
        <sphere radius="0.005" />
      </geometry>
    </collision>
  </link>
  <joint name="left_ankle_roll_joint" type="fixed">
    <origin xyz="0 0 -0.017558" rpy="0 0 0" />
    <parent link="left_ankle_pitch_link" />
    <child link="left_ankle_roll_link" />
  </joint>
  <link name="right_hip_pitch_link">
    <inertial>
      <origin xyz="0.002741 -0.047791 -0.02606" rpy="0 0 0" />
      <mass value="1.35" />
      <inertia ixx="0.001811" ixy="-3.68E-05" ixz="-3.44E-05" iyy="0.0014193" iyz="-0.000171" izz="0.0012812" />
    </inertial>
    <visual>
      <origin xyz="0 0 0" rpy="0 0 0" />
      <geometry>
        <mesh filename="meshes/right_hip_pitch_link.STL" />
      </geometry>
      <material name="dark" />
    </visual>
    <collision>
      <origin xyz="0 0 0" rpy="0 0 0" />
      <geometry>
        <mesh filename="meshes/right_hip_pitch_link.STL" />
      </geometry>
    </collision>
  </link>
  <joint name="right_hip_pitch_joint" type="fixed">
    <origin xyz="0 -0.064452 -0.1027" rpy="0 0 0" />
    <parent link="pelvis" />
    <child link="right_hip_pitch_link" />
  </joint>
  <link name="right_hip_roll_link">
    <inertial>
      <origin xyz="0.029812 0.001045 -0.087934" rpy="0 0 0" />
      <mass value="1.52" />
      <inertia ixx="0.0023773" ixy="3.8E-06" ixz="-0.0003908" iyy="0.0024123" iyz="-1.84E-05" izz="0.0016595" />
    </inertial>
    <visual>
      <origin xyz="0 0 0" rpy="0 0 0" />
      <geometry>
        <mesh filename="meshes/right_hip_roll_link.STL" />
      </geometry>
      <material name="white">
        <color rgba="0.7 0.7 0.7 1" />
      </material>
    </visual>
    <collision>
      <origin xyz="0 0 0" rpy="0 0 0" />
      <geometry>
        <mesh filename="meshes/right_hip_roll_link.STL" />
      </geometry>
    </collision>
  </link>
  <joint name="right_hip_roll_joint" type="fixed">
    <origin xyz="0 -0.052 -0.030465" rpy="0 -0.1749 0" />
    <parent link="right_hip_pitch_link" />
    <child link="right_hip_roll_link" />
  </joint>
  <link name="right_hip_yaw_link">
    <inertial>
      <origin xyz="-0.057709 0.010981 -0.15078" rpy="0 0 0" />
      <mass value="1.702" />
      <inertia ixx="0.0057774" ixy="0.0005411" ixz="-0.0023948" iyy="0.0076124" iyz="0.0007072" izz="0.003149" />
    </inertial>
    <visual>
      <origin xyz="0 0 0" rpy="0 0 0" />
      <geometry>
        <mesh filename="meshes/right_hip_yaw_link.STL" />
      </geometry>
      <material name="white">
        <color rgba="0.7 0.7 0.7 1" />
      </material>
    </visual>
    <collision>
      <origin xyz="0 0 0" rpy="0 0 0" />
      <geometry>
        <mesh filename="meshes/right_hip_yaw_link.STL" />
      </geometry>
    </collision>
  </link>
  <joint name="right_hip_yaw_joint" type="fixed">
    <origin xyz="0.025001 0 -0.12412" rpy="0 0 0" />
    <parent link="right_hip_roll_link" />
    <child link="right_hip_yaw_link" />
  </joint>
  <link name="right_knee_link">
    <inertial>
      <origin xyz="0.005457 -0.003964 -0.12074" rpy="0 0 0" />
      <mass value="1.932" />
      <inertia ixx="0.011329" ixy="-4.82E-05" ixz="4.49E-05" iyy="0.011277" iyz="0.0007146" izz="0.0015168" />
    </inertial>
    <visual>
      <origin xyz="0 0 0" rpy="0 0 0" />
      <geometry>
        <mesh filename="meshes/right_knee_link.STL" />
      </geometry>
      <material name="white">
        <color rgba="0.7 0.7 0.7 1" />
      </material>
    </visual>
    <collision>
      <origin xyz="0 0 0" rpy="0 0 0" />
      <geometry>
        <mesh filename="meshes/right_knee_link.STL" />
      </geometry>
    </collision>
  </link>
  <joint name="right_knee_joint" type="fixed">
    <origin xyz="-0.078273 -0.0021489 -0.17734" rpy="0 0.1749 0" />
    <parent link="right_hip_yaw_link" />
    <child link="right_knee_link" />
  </joint>
  <link name="right_ankle_pitch_link">
    <inertial>
      <origin xyz="-0.007269 0 0.011137" rpy="0 0 0" />
      <mass value="0.074" />
      <inertia ixx="8.4E-06" ixy="0" ixz="-2.9E-06" iyy="1.89E-05" iyz="0" izz="1.26E-05" />
    </inertial>
    <visual>
      <origin xyz="0 0 0" rpy="0 0 0" />
      <geometry>
        <mesh filename="meshes/right_ankle_pitch_link.STL" />
      </geometry>
      <material name="white">
        <color rgba="0.7 0.7 0.7 1" />
      </material>
    </visual>
    <collision>
      <origin xyz="0 0 0" rpy="0 0 0" />
      <geometry>
        <mesh filename="meshes/right_ankle_pitch_link.STL" />
      </geometry>
    </collision>
  </link>
  <joint name="right_ankle_pitch_joint" type="fixed">
    <origin xyz="0 9.4445E-05 -0.30001" rpy="0 0 0" />
    <parent link="right_knee_link" />
    <child link="right_ankle_pitch_link" />
  </joint>
  <link name="right_ankle_roll_link">
    <inertial>
      <origin xyz="0.026505 0 -0.016425" rpy="0 0 0" />
      <mass value="0.608" />
      <inertia ixx="0.0002231" ixy="-2E-07" ixz="8.91E-05" iyy="0.0016161" iyz="1E-07" izz="0.0016667" />
    </inertial>
    <visual>
      <origin xyz="0 0 0" rpy="0 0 0" />
      <geometry>
        <mesh filename="meshes/right_ankle_roll_link.STL" />
      </geometry>
      <material name="dark" />
    </visual>
    <collision>
      <origin xyz="-0.05 0.025 -0.03" rpy="0 0 0" />
      <geometry>
        <sphere radius="0.005" />
      </geometry>
    </collision>
    <collision>
      <origin xyz="-0.05 -0.025 -0.03" rpy="0 0 0" />
      <geometry>
        <sphere radius="0.005" />
      </geometry>
    </collision>
    <collision>
      <origin xyz="0.12 0.03 -0.03" rpy="0 0 0" />
      <geometry>
        <sphere radius="0.005" />
      </geometry>
    </collision>
    <collision>
      <origin xyz="0.12 -0.03 -0.03" rpy="0 0 0" />
      <geometry>
        <sphere radius="0.005" />
      </geometry>
    </collision>
  </link>
  <joint name="right_ankle_roll_joint" type="fixed">
    <origin xyz="0 0 -0.017558" rpy="0 0 0" />
    <parent link="right_ankle_pitch_link" />
    <child link="right_ankle_roll_link" />
  </joint>


  <link name="waist_yaw_link">
    <inertial>
      <origin xyz="0.003494 0.000233 0.018034" rpy="0 0 0" />
      <mass value="0.214" />
      <inertia ixx="0.00010673" ixy="2.703E-06" ixz="-7.631E-06" iyy="0.00010422" iyz="-2.01E-07" izz="0.0001625" />
    </inertial>
    <visual>
      <origin xyz="0 0 0" rpy="0 0 0" />
      <geometry>
        <mesh filename="meshes/waist_yaw_link_rev_1_0.STL" />
      </geometry>
      <material name="white">
        <color rgba="0.7 0.7 0.7 1" />
      </material>
    </visual>
  </link>
  <joint name="waist_yaw_joint" type="fixed">
    <origin xyz="0 0 0" rpy="0 0 0" />
    <parent link="pelvis" />
    <child link="waist_yaw_link" />
  </joint>
  <link name="waist_roll_link">
    <inertial>
      <origin xyz="0 2.3E-05 0" rpy="0 0 0" />
      <mass value="0.086" />
      <inertia ixx="7.079E-06" ixy="0" ixz="0" iyy="6.339E-06" iyz="0" izz="8.245E-06" />
    </inertial>
    <visual>
      <origin xyz="0 0 0" rpy="0 0 0" />
      <geometry>
        <mesh filename="meshes/waist_roll_link_rev_1_0.STL" />
      </geometry>
      <material name="white">
        <color rgba="0.7 0.7 0.7 1" />
      </material>
    </visual>
  </link>
  <joint name="waist_roll_joint" type="fixed">
    <origin xyz="-0.0039635 0 0.044" rpy="0 0 0" />
    <parent link="waist_yaw_link" />
    <child link="waist_roll_link" />
  </joint>
  <link name="torso_link">
    <inertial>
      <origin xyz="0.000931 0.000346 0.15082" rpy="0 0 0" />
      <mass value="6.78" />
      <inertia ixx="0.05905" ixy="3.3302E-05" ixz="-0.0017715" iyy="0.047014" iyz="-2.2399E-05" izz="0.025652" />
    </inertial>
    <visual>
      <origin xyz="0 0 0" rpy="0 0 0" />
      <geometry>
        <mesh filename="meshes/torso_link_rev_1_0.STL" />
      </geometry>
      <material name="white">
        <color rgba="0.7 0.7 0.7 1" />
      </material>
    </visual>
    <collision>
      <origin xyz="0 0 0" rpy="0 0 0" />
      <geometry>
        <mesh filename="meshes/torso_link_rev_1_0.STL" />
      </geometry>
    </collision>
  </link>
  <joint name="waist_pitch_joint" type="fixed">
    <origin xyz="0 0 0" rpy="0 0 0" />
    <parent link="waist_roll_link" />
    <child link="torso_link" />
  </joint>


  <joint name="logo_joint" type="fixed">
    <origin xyz="0.0039635 0 -0.044" rpy="0 0 0" />
    <parent link="torso_link" />
    <child link="logo_link" />
  </joint>
  <link name="logo_link">
    <inertial>
      <origin xyz="0 0 0" rpy="0 0 0" />
      <mass value="0.001" />
      <inertia ixx="1e-7" ixy="0" ixz="0" iyy="1e-7" iyz="0" izz="1e-7" />
    </inertial>
    <visual>
      <origin xyz="0 0 0" rpy="0 0 0" />
      <geometry>
        <mesh filename="meshes/logo_link.STL" />
      </geometry>
      <material name="dark" />
    </visual>
    <collision>
      <origin xyz="0 0 0" rpy="0 0 0" />
      <geometry>
        <mesh filename="meshes/logo_link.STL" />
      </geometry>
    </collision>
  </link>


  <link name="head_link">
    <inertial>
      <origin xyz="0.005267 0.000299 0.449869" rpy="0 0 0" />
      <mass value="1.036" />
      <inertia ixx="0.004085051" ixy="-2.543E-06" ixz="-6.9455E-05" iyy="0.004185212" iyz="-3.726E-06" izz="0.001807911" />
    </inertial>
    <visual>
      <origin xyz="0 0 0" rpy="0 0 0" />
      <geometry>
        <mesh filename="meshes/head_link.STL" />
      </geometry>
      <material name="dark" />
    </visual>
    <collision>
      <origin xyz="0 0 0" rpy="0 0 0" />
      <geometry>
        <mesh filename="meshes/head_link.STL" />
      </geometry>
    </collision>
  </link>
  <joint name="head_joint" type="fixed">
    <origin xyz="0.0039635 0 -0.044" rpy="0 0 0" />
    <parent link="torso_link" />
    <child link="head_link" />
  </joint>


  <link name="imu_in_torso" />
  <joint name="imu_in_torso_joint" type="fixed">
    <origin xyz="-0.03959 -0.00224 0.14792" rpy="0 0 0" />
    <parent link="torso_link" />
    <child link="imu_in_torso" />
  </joint>

  <link name="imu_in_pelvis" />
  <joint name="imu_in_pelvis_joint" type="fixed">
    <origin xyz="0.04525 0 -0.08339" rpy="0 0 0" />
    <parent link="pelvis" />
    <child link="imu_in_pelvis" />
  </joint>


  <link name="d435_link" />
  <joint name="d435_joint" type="fixed">
    <origin xyz="0.0576235 0.01753 0.42987" rpy="0 0.8307767239493009 0" />
    <parent link="torso_link" />
    <child link="d435_link" />
  </joint>


  <link name="mid360_link" />
  <joint name="mid360_joint" type="fixed">
    <origin xyz="0.0002835 0.00003 0.41618" rpy="0 0.04014257279586953 0" />
    <parent link="torso_link" />
    <child link="mid360_link" />
  </joint>


  <link name="left_shoulder_pitch_link">
    <inertial>
      <origin xyz="0 0.035892 -0.011628" rpy="0 0 0" />
      <mass value="0.718" />
      <inertia ixx="0.0004291" ixy="-9.2E-06" ixz="6.4E-06" iyy="0.000453" iyz="2.26E-05" izz="0.000423" />
    </inertial>
    <visual>
      <origin xyz="0 0 0" rpy="0 0 0" />
      <geometry>
        <mesh filename="meshes/left_shoulder_pitch_link.STL" />
      </geometry>
      <material name="white">
        <color rgba="0.7 0.7 0.7 1" />
      </material>
    </visual>
    <collision>
      <origin xyz="0 0.04 -0.01" rpy="0 1.5707963267948966 0" />
      <geometry>
        <cylinder radius="0.03" length="0.05" />
      </geometry>
    </collision>
  </link>
  <joint name="left_shoulder_pitch_joint" type="revolute">
    <origin xyz="0.0039563 0.10022 0.24778" rpy="0.27931 5.4949E-05 -0.00019159" />
    <parent link="torso_link" />
    <child link="left_shoulder_pitch_link" />
    <axis xyz="0 1 0" />
    <limit lower="-3.0892" upper="2.6704" effort="25" velocity="37" />
  </joint>
  <link name="left_shoulder_roll_link">
    <inertial>
      <origin xyz="-0.000227 0.00727 -0.063243" rpy="0 0 0" />
      <mass value="0.643" />
      <inertia ixx="0.0006177" ixy="-1E-06" ixz="8.7E-06" iyy="0.0006912" iyz="-5.3E-06" izz="0.0003894" />
    </inertial>
    <visual>
      <origin xyz="0 0 0" rpy="0 0 0" />
      <geometry>
        <mesh filename="meshes/left_shoulder_roll_link.STL" />
      </geometry>
      <material name="white">
        <color rgba="0.7 0.7 0.7 1" />
      </material>
    </visual>
    <collision>
      <origin xyz="-0.004 0.006 -0.053" rpy="0 0 0" />
      <geometry>
        <cylinder radius="0.03" length="0.03" />
      </geometry>
    </collision>
  </link>
  <joint name="left_shoulder_roll_joint" type="revolute">
    <origin xyz="0 0.038 -0.013831" rpy="-0.27925 0 0" />
    <parent link="left_shoulder_pitch_link" />
    <child link="left_shoulder_roll_link" />
    <axis xyz="1 0 0" />
    <limit lower="-1.5882" upper="2.2515" effort="25" velocity="37" />
  </joint>
  <link name="left_shoulder_yaw_link">
    <inertial>
      <origin xyz="0.010773 -0.002949 -0.072009" rpy="0 0 0" />
      <mass value="0.734" />
      <inertia ixx="0.0009988" ixy="7.9E-06" ixz="0.0001412" iyy="0.0010605" iyz="-2.86E-05" izz="0.0004354" />
    </inertial>
    <visual>
      <origin xyz="0 0 0" rpy="0 0 0" />
      <geometry>
        <mesh filename="meshes/left_shoulder_yaw_link.STL" />
      </geometry>
      <material name="white">
        <color rgba="0.7 0.7 0.7 1" />
      </material>
    </visual>
    <collision>
      <origin xyz="0 0 0" rpy="0 0 0" />
      <geometry>
        <mesh filename="meshes/left_shoulder_yaw_link.STL" />
      </geometry>
    </collision>
  </link>
  <joint name="left_shoulder_yaw_joint" type="revolute">
    <origin xyz="0 0.00624 -0.1032" rpy="0 0 0" />
    <parent link="left_shoulder_roll_link" />
    <child link="left_shoulder_yaw_link" />
    <axis xyz="0 0 1" />
    <limit lower="-2.618" upper="2.618" effort="25" velocity="37" />
  </joint>
  <link name="left_elbow_link">
    <inertial>
      <origin xyz="0.064956 0.004454 -0.010062" rpy="0 0 0" />
      <mass value="0.6" />
      <inertia ixx="0.0002891" ixy="6.53E-05" ixz="1.72E-05" iyy="0.0004152" iyz="-5.6E-06" izz="0.0004197" />
    </inertial>
    <visual>
      <origin xyz="0 0 0" rpy="0 0 0" />
      <geometry>
        <mesh filename="meshes/left_elbow_link.STL" />
      </geometry>
      <material name="white">
        <color rgba="0.7 0.7 0.7 1" />
      </material>
    </visual>
    <collision>
      <origin xyz="0 0 0" rpy="0 0 0" />
      <geometry>
        <mesh filename="meshes/left_elbow_link.STL" />
      </geometry>
    </collision>
  </link>
  <joint name="left_elbow_joint" type="revolute">
    <origin xyz="0.015783 0 -0.080518" rpy="0 0 0" />
    <parent link="left_shoulder_yaw_link" />
    <child link="left_elbow_link" />
    <axis xyz="0 1 0" />
    <limit lower="-1.0472" upper="2.0944" effort="25" velocity="37" />
  </joint>
  <joint name="left_wrist_roll_joint" type="revolute">
    <origin xyz="0.100 0.00188791 -0.010" rpy="0 0 0" />
    <axis xyz="1 0 0" />
    <parent link="left_elbow_link" />
    <child link="left_wrist_roll_link" />
    <limit effort="25" velocity="37" lower="-1.972222054" upper="1.972222054" />
  </joint>
  <link name="left_wrist_roll_link">
    <inertial>
      <origin xyz="0.01713944778 0.00053759094 0.00000048864" rpy="0 0 0" />
      <mass value="0.08544498" />
      <inertia ixx="0.00004821544023" ixy="-0.00000424511021" ixz="0.00000000510599" iyy="0.00003722899093" iyz="-0.00000000123525" izz="0.00005482106541" />
    </inertial>
    <visual>
      <origin xyz="0 0 0" rpy="0 0 0" />
      <geometry>
        <mesh filename="meshes/left_wrist_roll_link.STL" />
      </geometry>
      <material name="white">
        <color rgba="0.7 0.7 0.7 1" />
      </material>
    </visual>
    <collision>
      <origin xyz="0 0 0" rpy="0 0 0" />
      <geometry>
        <mesh filename="meshes/left_wrist_roll_link.STL" />
      </geometry>
    </collision>
  </link>
  <joint name="left_wrist_pitch_joint" type="revolute">
    <origin xyz="0.038 0 0" rpy="0 0 0" />
    <axis xyz="0 1 0" />
    <parent link="left_wrist_roll_link" />
    <child link="left_wrist_pitch_link" />
    <limit effort="5" velocity="22" lower="-1.614429558" upper="1.614429558" />
  </joint>
  <link name="left_wrist_pitch_link">
    <inertial>
      <origin xyz="0.02299989837 -0.00111685314 -0.00111658096" rpy="0 0 0" />
      <mass value="0.48404956" />
      <inertia ixx="0.00016579646273" ixy="-0.00001231206746" ixz="0.00001231699194" iyy="0.00042954057410" iyz="0.00000081417712" izz="0.00042953697654" />
    </inertial>
    <visual>
      <origin xyz="0 0 0" rpy="0 0 0" />
      <geometry>
        <mesh filename="meshes/left_wrist_pitch_link.STL" />
      </geometry>
      <material name="white">
        <color rgba="0.7 0.7 0.7 1" />
      </material>
    </visual>
    <collision>
      <origin xyz="0 0 0" rpy="0 0 0" />
      <geometry>
        <mesh filename="meshes/left_wrist_pitch_link.STL" />
      </geometry>
    </collision>
  </link>
  <joint name="left_wrist_yaw_joint" type="revolute">
    <origin xyz="0.046 0 0" rpy="0 0 0" />
    <axis xyz="0 0 1" />
    <parent link="left_wrist_pitch_link" />
    <child link="left_wrist_yaw_link" />
    <limit effort="5" velocity="22" lower="-1.614429558" upper="1.614429558" />
  </joint>
  <link name="left_wrist_yaw_link">
    <inertial>
      <origin xyz="0.02200381568 0.00049485096 0.00053861123" rpy="0 0 0" />
      <mass value="0.08457647" />
      <inertia ixx="0.00004929128828" ixy="-0.00000045735494" ixz="0.00000445867591" iyy="0.00005973338134" iyz="0.00000043217198" izz="0.00003928083826" />
    </inertial>
    <visual>
      <origin xyz="0 0 0" rpy="0 0 0" />
      <geometry>
        <mesh filename="meshes/left_wrist_yaw_link.STL" />
      </geometry>
      <material name="white">
        <color rgba="0.7 0.7 0.7 1" />
      </material>
    </visual>
    <collision>
      <origin xyz="0 0 0" rpy="0 0 0" />
      <geometry>
        <mesh filename="meshes/left_wrist_yaw_link.STL" />
      </geometry>
    </collision>
  </link>
  <link name="right_shoulder_pitch_link">
    <inertial>
      <origin xyz="0 -0.035892 -0.011628" rpy="0 0 0" />
      <mass value="0.718" />
      <inertia ixx="0.0004291" ixy="9.2E-06" ixz="6.4E-06" iyy="0.000453" iyz="-2.26E-05" izz="0.000423" />
    </inertial>
    <visual>
      <origin xyz="0 0 0" rpy="0 0 0" />
      <geometry>
        <mesh filename="meshes/right_shoulder_pitch_link.STL" />
      </geometry>
      <material name="white">
        <color rgba="0.7 0.7 0.7 1" />
      </material>
    </visual>
    <collision>
      <origin xyz="0 -0.04 -0.01" rpy="0 1.5707963267948966 0" />
      <geometry>
        <cylinder radius="0.03" length="0.05" />
      </geometry>
    </collision>
  </link>
  <joint name="right_shoulder_pitch_joint" type="revolute">
    <origin xyz="0.0039563 -0.10021 0.24778" rpy="-0.27931 5.4949E-05 0.00019159" />
    <parent link="torso_link" />
    <child link="right_shoulder_pitch_link" />
    <axis xyz="0 1 0" />
    <limit lower="-3.0892" upper="2.6704" effort="25" velocity="37" />
  </joint>
  <link name="right_shoulder_roll_link">
    <inertial>
      <origin xyz="-0.000227 -0.00727 -0.063243" rpy="0 0 0" />
      <mass value="0.643" />
      <inertia ixx="0.0006177" ixy="1E-06" ixz="8.7E-06" iyy="0.0006912" iyz="5.3E-06" izz="0.0003894" />
    </inertial>
    <visual>
      <origin xyz="0 0 0" rpy="0 0 0" />
      <geometry>
        <mesh filename="meshes/right_shoulder_roll_link.STL" />
      </geometry>
      <material name="white">
        <color rgba="0.7 0.7 0.7 1" />
      </material>
    </visual>
    <collision>
      <origin xyz="-0.004 -0.006 -0.053" rpy="0 0 0" />
      <geometry>
        <cylinder radius="0.03" length="0.03" />
      </geometry>
    </collision>
  </link>
  <joint name="right_shoulder_roll_joint" type="revolute">
    <origin xyz="0 -0.038 -0.013831" rpy="0.27925 0 0" />
    <parent link="right_shoulder_pitch_link" />
    <child link="right_shoulder_roll_link" />
    <axis xyz="1 0 0" />
    <limit lower="-2.2515" upper="1.5882" effort="25" velocity="37" />
  </joint>
  <link name="right_shoulder_yaw_link">
    <inertial>
      <origin xyz="0.010773 0.002949 -0.072009" rpy="0 0 0" />
      <mass value="0.734" />
      <inertia ixx="0.0009988" ixy="-7.9E-06" ixz="0.0001412" iyy="0.0010605" iyz="2.86E-05" izz="0.0004354" />
    </inertial>
    <visual>
      <origin xyz="0 0 0" rpy="0 0 0" />
      <geometry>
        <mesh filename="meshes/right_shoulder_yaw_link.STL" />
      </geometry>
      <material name="white">
        <color rgba="0.7 0.7 0.7 1" />
      </material>
    </visual>
    <collision>
      <origin xyz="0 0 0" rpy="0 0 0" />
      <geometry>
        <mesh filename="meshes/right_shoulder_yaw_link.STL" />
      </geometry>
    </collision>
  </link>
  <joint name="right_shoulder_yaw_joint" type="revolute">
    <origin xyz="0 -0.00624 -0.1032" rpy="0 0 0" />
    <parent link="right_shoulder_roll_link" />
    <child link="right_shoulder_yaw_link" />
    <axis xyz="0 0 1" />
    <limit lower="-2.618" upper="2.618" effort="25" velocity="37" />
  </joint>
  <link name="right_elbow_link">
    <inertial>
      <origin xyz="0.064956 -0.004454 -0.010062" rpy="0 0 0" />
      <mass value="0.6" />
      <inertia ixx="0.0002891" ixy="-6.53E-05" ixz="1.72E-05" iyy="0.0004152" iyz="5.6E-06" izz="0.0004197" />
    </inertial>
    <visual>
      <origin xyz="0 0 0" rpy="0 0 0" />
      <geometry>
        <mesh filename="meshes/right_elbow_link.STL" />
      </geometry>
      <material name="white">
        <color rgba="0.7 0.7 0.7 1" />
      </material>
    </visual>
    <collision>
      <origin xyz="0 0 0" rpy="0 0 0" />
      <geometry>
        <mesh filename="meshes/right_elbow_link.STL" />
      </geometry>
    </collision>
  </link>
  <joint name="right_elbow_joint" type="revolute">
    <origin xyz="0.015783 0 -0.080518" rpy="0 0 0" />
    <parent link="right_shoulder_yaw_link" />
    <child link="right_elbow_link" />
    <axis xyz="0 1 0" />
    <limit lower="-1.0472" upper="2.0944" effort="25" velocity="37" />
  </joint>
  <joint name="right_wrist_roll_joint" type="revolute">
    <origin xyz="0.100 -0.00188791 -0.010" rpy="0 0 0" />
    <axis xyz="1 0 0" />
    <parent link="right_elbow_link" />
    <child link="right_wrist_roll_link" />
    <limit effort="25" velocity="37" lower="-1.972222054" upper="1.972222054" />
  </joint>
  <link name="right_wrist_roll_link">
    <inertial>
      <origin xyz="0.01713944778 -0.00053759094 0.00000048864" rpy="0 0 0" />
      <mass value="0.08544498" />
      <inertia ixx="0.00004821544023" ixy="0.00000424511021" ixz="0.00000000510599" iyy="0.00003722899093" iyz="0.00000000123525" izz="0.00005482106541" />
    </inertial>
    <visual>
      <origin xyz="0 0 0" rpy="0 0 0" />
      <geometry>
        <mesh filename="meshes/right_wrist_roll_link.STL" />
      </geometry>
      <material name="white">
        <color rgba="0.7 0.7 0.7 1" />
      </material>
    </visual>
    <collision>
      <origin xyz="0 0 0" rpy="0 0 0" />
      <geometry>
        <mesh filename="meshes/right_wrist_roll_link.STL" />
      </geometry>
    </collision>
  </link>
  <joint name="right_wrist_pitch_joint" type="revolute">
    <origin xyz="0.038 0 0" rpy="0 0 0" />
    <axis xyz="0 1 0" />
    <parent link="right_wrist_roll_link" />
    <child link="right_wrist_pitch_link" />
    <limit effort="5" velocity="22" lower="-1.614429558" upper="1.614429558" />
  </joint>
  <link name="right_wrist_pitch_link">
    <inertial>
      <origin xyz="0.02299989837 0.00111685314 -0.00111658096" rpy="0 0 0" />
      <mass value="0.48404956" />
      <inertia ixx="0.00016579646273" ixy="0.00001231206746" ixz="0.00001231699194" iyy="0.00042954057410" iyz="-0.00000081417712" izz="0.00042953697654" />
    </inertial>
    <visual>
      <origin xyz="0 0 0" rpy="0 0 0" />
      <geometry>
        <mesh filename="meshes/right_wrist_pitch_link.STL" />
      </geometry>
      <material name="white">
        <color rgba="0.7 0.7 0.7 1" />
      </material>
    </visual>
    <collision>
      <origin xyz="0 0 0" rpy="0 0 0" />
      <geometry>
        <mesh filename="meshes/right_wrist_pitch_link.STL" />
      </geometry>
    </collision>
  </link>
  <joint name="right_wrist_yaw_joint" type="revolute">
    <origin xyz="0.046 0 0" rpy="0 0 0" />
    <axis xyz="0 0 1" />
    <parent link="right_wrist_pitch_link" />
    <child link="right_wrist_yaw_link" />
    <limit effort="5" velocity="22" lower="-1.614429558" upper="1.614429558" />
  </joint>
  <link name="right_wrist_yaw_link">
    <inertial>
      <origin xyz="0.02200381568 -0.00049485096 0.00053861123" rpy="0 0 0" />
      <mass value="0.08457647" />
      <inertia ixx="0.00004929128828" ixy="0.00000045735494" ixz="0.00000445867591" iyy="0.00005973338134" iyz="-0.00000043217198" izz="0.00003928083826" />
    </inertial>
    <visual>
      <origin xyz="0 0 0" rpy="0 0 0" />
      <geometry>
        <mesh filename="meshes/right_wrist_yaw_link.STL" />
      </geometry>
      <material name="white">
        <color rgba="0.7 0.7 0.7 1" />
      </material>
    </visual>
    <collision>
      <origin xyz="0 0 0" rpy="0 0 0" />
      <geometry>
        <mesh filename="meshes/right_wrist_yaw_link.STL" />
      </geometry>
    </collision>
  </link>


  <joint name="left_base_joint" type="fixed">
    <origin xyz="0.0415 0 0" rpy="3.1415926535 1.5707963267 3.1415926535" />
    <parent link="left_wrist_yaw_link" />
    <child link="left_base_link" />
  </joint>
  <link name="left_base_link">
    <inertial>
      <origin xyz="0.000631583768841232 -4.98983354635385E-11 0.0185710296512339" rpy="0 0 0" />
      <mass value="0.0793945339384899" />
      <inertia ixx="2.73302961659096E-05" ixy="-1.14020192447604E-12" ixz="2.86317776549754E-08" iyy="2.62165201865506E-05" iyz="-9.86803596469321E-13" izz="3.56824415579562E-05" />
    </inertial>
    <visual>
      <origin xyz="0 0 0" rpy="0 0 0" />
      <geometry>
        <mesh filename="meshes/left_base_link.STL" />
      </geometry>
      <material name="">
        <color rgba="1 1 1 1" />
      </material>
    </visual>
    <collision>
      <origin xyz="0 0 0" rpy="0 0 0" />
      <geometry>
        <mesh filename="meshes/left_base_link.STL" />
      </geometry>
    </collision>
  </link>
  <link name="left_thumb_1">
    <inertial>
      <origin xyz="-0.00015 0.00544 -0.0048200000000000005" rpy="0 0 0" />
      <mass value="0.016800000000000002" />
      <inertia ixx="7.3387e-07" ixy="1.436e-08" ixz="-1.11e-09" iyy="2.7925e-07" iyz="3.296e-08" izz="5.8189e-07" />
    </inertial>
    <visual>
      <origin xyz="0 0 0" rpy="0 0 0" />
      <geometry>
        <mesh filename="meshes/left_thumb_1.STL" />
      </geometry>
      <material name="">
        <color rgba="1 1 1 1" />
      </material>
    </visual>
    <collision>
      <origin xyz="0 0 0" rpy="0 0 0" />
      <geometry>
        <mesh filename="meshes/left_thumb_1.STL" />
      </geometry>
    </collision>
  </link>
  
  <joint name="left_thumb_1_joint" type="revolute">
    <origin xyz="0.01836 -0.027241 0.070511" rpy="0 0 0" />
    <parent link="left_base_link" />
    <child link="left_thumb_1" />
    <axis xyz="8.7274E-05 0 1" />
    <limit lower="0" upper="2.0943951023931953" effort="1" velocity="2" />
  </joint>
  <link name="left_thumb_2">
    <inertial>
      <origin xyz="-0.0238 0.01042 0.00478" rpy="0 0 0" />
      <mass value="0.06526" />
      <inertia ixx="1.378224e-05" ixy="-5.95663e-06" ixz="-1.9799999999999998e-09" iyy="1.1840129999999999e-05" iyz="-7.070000000000001e-09" izz="2.249189e-05" />
    </inertial>
    <visual>
      <origin xyz="0 0 0" rpy="0 0 0" />
      <geometry>
        <mesh filename="meshes/left_thumb_2.STL" />
      </geometry>
      <material name="">
        <color rgba="0.25 0.25 0.25 1" />
      </material>
    </visual>
    <collision>
      <origin xyz="0 0 0" rpy="0 0 0" />
      <geometry>
        <mesh filename="meshes/left_thumb_2.STL" />
      </geometry>
    </collision>
  </link>
  <joint name="left_thumb_2_joint" type="revolute">
    <origin xyz="0.005034 -0.01349 -0.0049121" rpy="1.5707 0 -1.5708" />
    <parent link="left_thumb_1" />
    <child link="left_thumb_2" />
    <axis xyz="0 0 1" />
    <limit lower="0" upper="0.4745550236172582" effort="1" velocity="2" />
  </joint>
  <link name="left_thumb_3">
    <inertial>
      <origin xyz="-0.01255 0.00331 0.00799" rpy="0 0 0" />
      <mass value="0.01333" />
      <inertia ixx="1.41987e-06" ixy="-1.4979e-07" ixz="-6.3e-10" iyy="1.18482e-06" iyz="-1.76e-09" izz="1.6920999999999999e-06" />
    </inertial>
    <visual>
      <origin xyz="0 0 0" rpy="0 0 0" />
      <geometry>
        <mesh filename="meshes/left_thumb_3.STL" />
      </geometry>
      <material name="">
        <color rgba="0.25 0.25 0.25 1" />
      </material>
    </visual>
    <collision>
      <origin xyz="0 0 0" rpy="0 0 0" />
      <geometry>
        <mesh filename="meshes/left_thumb_3.STL" />
      </geometry>
    </collision>
  </link>
  <joint name="left_thumb_3_joint" type="revolute">
    <origin xyz="0.033907 0.034601 -0.0029656" rpy="0 0 0" />
    <parent link="left_thumb_2" />
    <child link="left_thumb_3" />
    <axis xyz="0 0 1" />
    <limit lower="0" upper="3.14" effort="1" velocity="2" />
      <mimic joint="left_thumb_2_joint" multiplier="1.2953" offset="0" />
  </joint>
  <link name="left_thumb_4">
    <inertial>
      <origin xyz="-0.010199999999999999 0.00886 0.0067" rpy="0 0 0" />
      <mass value="0.011439999999999999" />
      <inertia ixx="9.4221e-07" ixy="-1.6288e-07" ixz="-0.0" iyy="3.9966e-07" iyz="0.0" izz="9.478099999999999e-07" />
    </inertial>
    <visual>
      <origin xyz="0 0 0" rpy="0 0 0" />
      <geometry>
        <mesh filename="meshes/left_thumb_4.STL" />
      </geometry>
      <material name="">
        <color rgba="0.25 0.25 0.25 1" />
      </material>
    </visual>
    <collision>
      <origin xyz="0 0 0" rpy="0 0 0" />
      <geometry>
        <mesh filename="meshes/left_thumb_4.STL" />
      </geometry>
    </collision>
  </link>
  <joint name="left_thumb_4_joint" type="revolute">
    <origin xyz="0.01441 0.014648 0.0013" rpy="0 0 0" />
    <parent link="left_thumb_3" />
    <child link="left_thumb_4" />
    <axis xyz="0 0 1" />
    <limit lower="0" upper="3.14" effort="1" velocity="2" />
      <mimic joint="left_thumb_3_joint" multiplier="0.8962" offset="0" />
  </joint>
  <link name="left_thumb_tip">
    <visual>
      <origin
        xyz="0 0 0"
        rpy="0 0 0" />
      <geometry>
        <sphere radius="0.001"/>
      </geometry>
      <material name="green">
        <color rgba="0 1 0 1" />
      </material>
    </visual>
  </link>
  <joint name="left_thumb_tip_joint" type="fixed">
    <parent link="left_thumb_4"/>
    <child link="left_thumb_tip"/>
    <origin rpy="0 0 0" xyz="0.014 0.025 0.0065"/>
  </joint>
  <link name="left_index_1">
    <inertial>
      <origin xyz="0.00046 0.01509 0.0060999999999999995" rpy="0 0 0" />
      <mass value="0.01111" />
      <inertia ixx="2.04599e-06" ixy="3.703e-08" ixz="1.77e-09" iyy="5.4029e-07" iyz="-9.149e-08" izz="2.0895e-06" />
    </inertial>
    <visual>
      <origin xyz="0 0 0" rpy="0 0 0" />
      <geometry>
        <mesh filename="meshes/left_index_1.STL" />
      </geometry>
      <material name="">
        <color rgba="0.25 0.25 0.25 1" />
      </material>
    </visual>
    <collision>
      <origin xyz="0 0 0" rpy="0 0 0" />
      <geometry>
        <mesh filename="meshes/left_index_1.STL" />
      </geometry>
    </collision>
  </link>
  <joint name="left_index_1_joint" type="revolute">
    <origin xyz="0.00070753 -0.034377 0.13554" rpy="1.6319 0 0" />
    <parent link="left_base_link" />
    <child link="left_index_1" />
    <axis xyz="0 0 -1" />
    <limit lower="0" upper="1.5285593588966337" effort="1" velocity="2" />
  </joint>
  <link name="left_index_2">
    <inertial>
      <origin xyz="-0.00436 0.01623 0.005019999999999999" rpy="0 0 0" />
      <mass value="0.0103" />
      <inertia ixx="1.5669000000000002e-06" ixy="2.2414e-07" ixz="1.3699999999999999e-08" iyy="2.9717e-07" iyz="-7.84e-08" izz="1.5746300000000001e-06" />
    </inertial>
    <visual>
      <origin xyz="0 0 0" rpy="0 0 0" />
      <geometry>
        <mesh filename="meshes/left_index_2.STL" />
      </geometry>
      <material name="">
        <color rgba="0.25 0.25 0.25 1" />
      </material>
    </visual>
    <collision>
      <origin xyz="0 0 0" rpy="0 0 0" />
      <geometry>
        <mesh filename="meshes/left_index_2.STL" />
      </geometry>
    </collision>
  </link>
  <joint name="left_index_2_joint" type="revolute">
    <origin xyz="0.0031056 0.032854 -0.001" rpy="0 0 0" />
    <parent link="left_index_1" />
    <child link="left_index_2" />
    <axis xyz="0 0 -1" />
    <limit lower="0" upper="3.14" effort="1" velocity="2" />
      <mimic joint="left_index_1_joint" multiplier="1.1545" offset="0" />
  </joint>
  <link name="left_index_tip">
    <visual>
      <origin
        xyz="0 0 0"
        rpy="0 0 0" />
      <geometry>
        <sphere radius="0.001"/>
      </geometry>
      <material name="green">
        <color rgba="0 1 0 1" />
      </material>
    </visual>
  </link>
  <joint name="left_index_tip_joint" type="fixed">
    <parent link="left_index_2"/>
    <child link="left_index_tip"/>
    <origin rpy="0 0 0" xyz="0.006 0.0365 -0.006"/>
  </joint>

  <link name="left_middle_1">
    <inertial>
      <origin xyz="0.00046 0.01468 0.00701" rpy="0 0 0" />
      <mass value="0.01111" />
      <inertia ixx="2.04599e-06" ixy="3.707e-08" ixz="-4.9e-10" iyy="5.3491e-07" iyz="3.6e-09" izz="2.09487e-06" />
    </inertial>
    <visual>
      <origin xyz="0 0 0" rpy="0 0 0" />
      <geometry>
        <mesh filename="meshes/left_middle_1.STL" />
      </geometry>
      <material name="">
        <color rgba="0.25 0.25 0.25 1" />
      </material>
    </visual>
    <collision>
      <origin xyz="0 0 0" rpy="0 0 0" />
      <geometry>
        <mesh filename="meshes/left_middle_1.STL" />
      </geometry>
    </collision>
  </link>
  <joint name="left_middle_1_joint" type="revolute">
    <origin xyz="0.00070746 -0.015767 0.13648" rpy="1.5708 0 0" />
    <parent link="left_base_link" />
    <child link="left_middle_1" />
    <axis xyz="0 0 -1" />
    <limit lower="0" upper="1.5285593588966337" effort="1" velocity="2" />
  </joint>
  <link name="left_middle_2">
    <inertial>
      <origin xyz="-0.004019999999999999 0.01731 0.006" rpy="0 0 0" />
      <mass value="0.01122" />
      <inertia ixx="1.92755e-06" ixy="2.9305e-07" ixz="-1.0000000000000001e-11" iyy="3.2973000000000003e-07" iyz="1.0000000000000001e-11" izz="1.95229e-06" />
    </inertial>
    <visual>
      <origin xyz="0 0 0" rpy="0 0 0" />
      <geometry>
        <mesh filename="meshes/left_middle_2.STL" />
      </geometry>
      <material name="">
        <color rgba="0.25 0.25 0.25 1" />
      </material>
    </visual>
    <collision>
      <origin xyz="0 0 0" rpy="0 0 0" />
      <geometry>
        <mesh filename="meshes/left_middle_2.STL" />
      </geometry>
    </collision>
  </link>
  <joint name="left_middle_2_joint" type="revolute">
    <origin xyz="0.0031056 0.032854 -0.001" rpy="0 0 0" />
    <parent link="left_middle_1" />
    <child link="left_middle_2" />
    <axis xyz="0 0 -1" />
    <limit lower="0" upper="3.14" effort="1" velocity="2" />
      <mimic joint="left_middle_1_joint" multiplier="1.1545" offset="0" />
  </joint>
  <link name="left_middle_tip">
    <visual>
      <origin
        xyz="0 0 0"
        rpy="0 0 0" />
      <geometry>
        <sphere radius="0.001"/>
      </geometry>
      <material name="green">
        <color rgba="0 1 0 1" />
      </material>
    </visual>
  </link>
  <joint name="left_middle_tip_joint" type="fixed">
    <parent link="left_middle_2"/>
    <child link="left_middle_tip"/>
    <origin rpy="0 0 0" xyz="0.007 0.039 -0.006"/>
  </joint>

  <link name="left_ring_1">
    <inertial>
      <origin xyz="0.00046 0.0143 0.00777" rpy="0 0 0" />
      <mass value="0.01111" />
      <inertia ixx="2.04599e-06" ixy="3.699e-08" ixz="-2.43e-09" iyy="5.395599999999999e-07" iyz="8.511e-08" izz="2.09023e-06" />
    </inertial>
    <visual>
      <origin xyz="0 0 0" rpy="0 0 0" />
      <geometry>
        <mesh filename="meshes/left_ring_1.STL" />
      </geometry>
      <material name="">
        <color rgba="0.25 0.25 0.25 1" />
      </material>
    </visual>
    <collision>
      <origin xyz="0 0 0" rpy="0 0 0" />
      <geometry>
        <mesh filename="meshes/left_ring_1.STL" />
      </geometry>
    </collision>
  </link>
  <joint name="left_ring_1_joint" type="revolute">
    <origin xyz="0.00070746 0.0030876 0.13643" rpy="1.5184 0 0" />
    <parent link="left_base_link" />
    <child link="left_ring_1" />
    <axis xyz="0 0 -1" />
    <limit lower="0" upper="1.5285593588966337" effort="1" velocity="2" />
  </joint>
  <link name="left_ring_2">
    <inertial>
      <origin xyz="-0.00436 0.015560000000000001 0.0068200000000000005" rpy="0 0 0" />
      <mass value="0.0103" />
      <inertia ixx="1.5669000000000002e-06" ixy="2.2425e-07" ixz="-1.1759999999999999e-08" iyy="2.959e-07" iyz="6.729e-08" izz="1.5758900000000002e-06" />
    </inertial>
    <visual>
      <origin xyz="0 0 0" rpy="0 0 0" />
      <geometry>
        <mesh filename="meshes/left_ring_2.STL" />
      </geometry>
      <material name="">
        <color rgba="0.25 0.25 0.25 1" />
      </material>
    </visual>
    <collision>
      <origin xyz="0 0 0" rpy="0 0 0" />
      <geometry>
        <mesh filename="meshes/left_ring_2.STL" />
      </geometry>
    </collision>
  </link>
  <joint name="left_ring_2_joint" type="revolute">
    <origin xyz="0.0031056 0.032854 -0.001" rpy="0 0 0" />
    <parent link="left_ring_1" />
    <child link="left_ring_2" />
    <axis xyz="0 0 -1" />
    <limit lower="0" upper="3.14" effort="1" velocity="2" />
      <mimic joint="left_ring_1_joint" multiplier="1.1545" offset="0" />
  </joint>
  <link name="left_ring_tip">
    <visual>
      <origin
        xyz="0 0 0"
        rpy="0 0 0" />
      <geometry>
        <sphere radius="0.001"/>
      </geometry>
      <material name="green">
        <color rgba="0 1 0 1" />
      </material>
    </visual>
  </link>
  <joint name="left_ring_tip_joint" type="fixed">
    <parent link="left_ring_2"/>
    <child link="left_ring_tip"/>
    <origin rpy="0 0 0" xyz="0.006 0.036 -0.006"/>
  </joint>

  <link name="left_little_1">
    <inertial>
      <origin xyz="0.00046 0.013869999999999999 0.0085" rpy="0 0 0" />
      <mass value="0.01111" />
      <inertia ixx="2.04599e-06" ixy="3.6810000000000003e-08" ixz="-4.360000000000001e-09" iyy="5.527e-07" iyz="1.6568e-07" izz="2.07708e-06" />
    </inertial>
    <visual>
      <origin xyz="0 0 0" rpy="0 0 0" />
      <geometry>
        <mesh filename="meshes/left_little_1.STL" />
      </geometry>
      <material name="">
        <color rgba="0.25 0.25 0.25 1" />
      </material>
    </visual>
    <collision>
      <origin xyz="0 0 0" rpy="0 0 0" />
      <geometry>
        <mesh filename="meshes/left_little_1.STL" />
      </geometry>
    </collision>
  </link>
  <joint name="left_little_1_joint" type="revolute">
    <origin xyz="0.00070753 0.021094 0.13531" rpy="1.4661 0 0" />
    <parent link="left_base_link" />
    <child link="left_little_1" />
    <axis xyz="0 0 -1" />
    <limit lower="0" upper="1.5285593588966337" effort="1" velocity="2" />
  </joint>
  <link name="left_little_2">
    <inertial>
      <origin xyz="-0.004070000000000001 0.01192 0.00728" rpy="0 0 0" />
      <mass value="0.00839" />
      <inertia ixx="9.3539e-07" ixy="1.6843e-07" ixz="-1.7670000000000002e-08" iyy="2.4681e-07" iyz="7.359e-08" izz="9.379400000000001e-07" />
    </inertial>
    <visual>
      <origin xyz="0 0 0" rpy="0 0 0" />
      <geometry>
        <mesh filename="meshes/left_little_2.STL" />
      </geometry>
      <material name="">
        <color rgba="0.25 0.25 0.25 1" />
      </material>
    </visual>
    <collision>
      <origin xyz="0 0 0" rpy="0 0 0" />
      <geometry>
        <mesh filename="meshes/left_little_2.STL" />
      </geometry>
    </collision>
  </link>
  <joint name="left_little_2_joint" type="revolute">
    <origin xyz="0.0031057 0.032854 -0.001" rpy="0 0 0" />
    <parent link="left_little_1" />
    <child link="left_little_2" />
    <axis xyz="0 0 -1" />
    <limit lower="0" upper="3.14" effort="1" velocity="2" />
      <mimic joint="left_little_1_joint" multiplier="1.1545" offset="0" />
  </joint>
  <link name="left_little_tip">
    <visual>
      <origin
        xyz="0 0 0"
        rpy="0 0 0" />
      <geometry>
        <sphere radius="0.001"/>
      </geometry>
      <material name="green">
        <color rgba="0 1 0 1" />
      </material>
    </visual>
  </link>
  <joint name="left_little_tip_joint" type="fixed">
    <parent link="left_little_2"/>
    <child link="left_little_tip"/>
    <origin rpy="0 0 0" xyz="0.006 0.029 -0.006"/>
  </joint>
  <link name="left_plam_1">
    <inertial>
      <origin xyz="-0.00132 0.00039 0.07415000000000001" rpy="0 0 0" />
      <mass value="0.41238" />
      <inertia ixx="0.00078835939" ixy="-8.875e-07" ixz="3.202881e-05" iyy="0.00066648352" iyz="1.4681199999999999e-06" izz="0.00026678122" />
    </inertial>
    <visual>
      <origin xyz="0 0 0" rpy="0 0 0" />
      <geometry>
        <mesh filename="meshes/left_plam_1.STL" />
      </geometry>
      <material name="">
        <color rgba="1 1 1 1" />
      </material>
    </visual>
    <collision>
      <origin xyz="0 0 0" rpy="0 0 0" />
      <geometry>
        <mesh filename="meshes/left_plam_1.STL" />
      </geometry>
    </collision>
  </link>
  <joint name="left_plam_1_joint" type="fixed">
    <origin xyz="0 0 0.0305" rpy="0 0 0" />
    <parent link="left_base_link" />
    <child link="left_plam_1" />
    <axis xyz="0 0 0" />
  </joint>
  <link name="left_plam_2">
    <inertial>
      <origin xyz="0.00738877558367422 0.00286851435787733 0.0491990009538881" rpy="0 0 0" />
      <mass value="0.01" />
      <inertia ixx="7.42627311403438E-05" ixy="-1.51062288185372E-06" ixz="-1.38221866903039E-06" iyy="4.54002453711238E-05" iyz="3.52845387182101E-06" izz="3.50303789099898E-05" />
    </inertial>
    <visual>
      <origin xyz="0 0 0" rpy="0 0 0" />
      <geometry>
        <mesh filename="meshes/left_plam_2.STL" />
      </geometry>
      <material name="">
        <color rgba="0.25 0.25 0.25 1" />
      </material>
    </visual>
    <collision>
      <origin xyz="0 0 0" rpy="0 0 0" />
      <geometry>
        <mesh filename="meshes/left_plam_2.STL" />
      </geometry>
    </collision>
  </link>
  <joint name="left_plam_2_joint" type="fixed">
    <origin xyz="0 0 0" rpy="0 0 0" />
    <parent link="left_plam_1" />
    <child link="left_plam_2" />
    <axis xyz="0 0 0" />
  </joint>
  <link name="left_plam_3">
    <inertial>
      <origin xyz="-0.0145080707705958 -0.00297062755371721 0.0599886430688916" rpy="0 0 0" />
      <mass value="0.01" />
      <inertia ixx="7.44290151295326E-05" ixy="2.11550341708188E-06" ixz="3.5267344320077E-07" iyy="4.06594932990061E-05" iyz="-3.15566621908941E-06" izz="4.24832389559144E-05" />
    </inertial>
    <visual>
      <origin xyz="0 0 0" rpy="0 0 0" />
      <geometry>
        <mesh filename="meshes/left_plam_3.STL" />
      </geometry>
      <material name="">
        <color rgba="1 1 1 1" />
      </material>
    </visual>
    <collision>
      <origin xyz="0 0 0" rpy="0 0 0" />
      <geometry>
        <mesh filename="meshes/left_plam_3.STL" />
      </geometry>
    </collision>
  </link>
  <joint name="left_plam_3_joint" type="fixed">
    <origin xyz="0 0 0" rpy="0 0 0" />
    <parent link="left_plam_2" />
    <child link="left_plam_3" />
    <axis xyz="0 0 0" />
  </joint>
  <link name="left_plam_force_sensor">
    <inertial>
      <origin xyz="0.00135083432691963 -0.00241176672948407 -0.00177409386471654" rpy="0 0 0" />
      <mass value="0.00449423213489162" />
      <inertia ixx="2.77343430370559E-07" ixy="9.29194202733673E-12" ixz="-1.13995686775868E-12" iyy="1.25941926345234E-06" iyz="5.96425032363731E-09" izz="1.53055306696602E-06" />
    </inertial>
    <visual>
      <origin xyz="0 0 0" rpy="0 0 0" />
      <geometry>
        <mesh filename="meshes/left_plam_force_sensor.STL" />
      </geometry>
      <material name="">
        <color rgba="0.25 0.25 0.25 1" />
      </material>
    </visual>
    <collision>
      <origin xyz="0 0 0" rpy="0 0 0" />
      <geometry>
        <mesh filename="meshes/left_plam_force_sensor.STL" />
      </geometry>
    </collision>
  </link>
  <joint name="left_plam_force_sensor_joint" type="fixed">
    <origin xyz="0.01594 -0.0013505 0.073746" rpy="1.5708 0 1.5708" />
    <parent link="left_plam_2" />
    <child link="left_plam_force_sensor" />
    <axis xyz="0 0 0" />
  </joint>
  
  
  




  <joint name="right_base_joint" type="fixed">
    <origin xyz="0.0415 0 0" rpy="0 1.5707963267 0" />
    <parent link="right_wrist_yaw_link" />
    <child link="right_base_link" />
  </joint>
  <link name="right_base_link">
    <inertial>
      <origin xyz="0.000631584180168987 1.55468476565051E-09 0.0185710308410627" rpy="0 0 0" />
      <mass value="0.0793945003608915" />
      <inertia ixx="2.73302869871105E-05" ixy="4.73396056660905E-13" ixz="2.86328005285174E-08" iyy="2.62165141408126E-05" iyz="1.90463743334758E-12" izz="3.5682432554866E-05" />
    </inertial>
    <visual>
      <origin xyz="0 0 0" rpy="0 0 0" />
      <geometry>
        <mesh filename="meshes/right_base_link.STL" />
      </geometry>
      <material name="">
        <color rgba="1 1 1 1" />
      </material>
    </visual>
    <collision>
      <origin xyz="0 0 0" rpy="0 0 0" />
      <geometry>
        <mesh filename="meshes/right_base_link.STL" />
      </geometry>
    </collision>
  </link>
  <link name="right_plam_1">
    <inertial>
      <origin xyz="-0.00132 0.00039 0.07415000000000001" rpy="0 0 0" />
      <mass value="0.41238" />
      <inertia ixx="0.00078835939" ixy="8.875e-07" ixz="3.202881e-05" iyy="0.00066648352" iyz="-1.4681199999999999e-06" izz="0.00026678122" />
    </inertial>
    <visual>
      <origin xyz="0 0 0" rpy="0 0 0" />
      <geometry>
        <mesh filename="meshes/right_plam_1.STL" />
      </geometry>
      <material name="">
        <color rgba="0.866666666666667 0.866666666666667 0.890196078431372 1" />
      </material>
    </visual>
    <collision>
      <origin xyz="0 0 0" rpy="0 0 0" />
      <geometry>
        <mesh filename="meshes/right_plam_1.STL" />
      </geometry>
    </collision>
  </link>
  <joint name="right_plam_1_joint" type="fixed">
    <origin xyz="0 0 0.0305" rpy="0 0 0" />
    <parent link="right_base_link" />
    <child link="right_plam_1" />
    <axis xyz="0 0 0" />
  </joint>
  <link name="right_plam_2">
    <inertial>
      <origin xyz="0.00780742986700294 -0.00181684242732992 0.0484726926194218" rpy="0 0 0" />
      <mass value="0.01" />
      <inertia ixx="7.53775883572448E-05" ixy="1.67198206435067E-06" ixz="-1.35138361804759E-06" iyy="4.62768852730386E-05" iyz="-3.66656859035162E-06" izz="3.55364070799627E-05" />
    </inertial>
    <visual>
      <origin xyz="0 0 0" rpy="0 0 0" />
      <geometry>
        <mesh filename="meshes/right_plam_2.STL" />
      </geometry>
      <material name="">
        <color rgba="0.25 0.25 0.25 1" />
      </material>
    </visual>
    <collision>
      <origin xyz="0 0 0" rpy="0 0 0" />
      <geometry>
        <mesh filename="meshes/right_plam_2.STL" />
      </geometry>
    </collision>
  </link>
  <joint name="right_plam_2_joint" type="fixed">
    <origin xyz="0 0 0" rpy="0 0 0" />
    <parent link="right_plam_1" />
    <child link="right_plam_2" />
    <axis xyz="0 0 0" />
  </joint>
  <link name="right_plam_3">
    <inertial>
      <origin xyz="-0.0145087315400233 0.00297298156011864 0.0599801851672911" rpy="0 0 0" />
      <mass value="0.01" />
      <inertia ixx="7.44229190374554E-05" ixy="-2.11457285174435E-06" ixz="3.53419391577662E-07" iyy="4.06574859268604E-05" iyz="3.15838633047347E-06" izz="4.24785219389853E-05" />
    </inertial>
    <visual>
      <origin xyz="0 0 0" rpy="0 0 0" />
      <geometry>
        <mesh filename="meshes/right_plam_3.STL" />
      </geometry>
      <material name="">
        <color rgba="1 1 1 1" />
      </material>
    </visual>
    <collision>
      <origin xyz="0 0 0" rpy="0 0 0" />
      <geometry>
        <mesh filename="meshes/right_plam_3.STL" />
      </geometry>
    </collision>
  </link>
  <joint name="right_plam_3_joint" type="fixed">
    <origin xyz="0 0 0" rpy="0 0 0" />
    <parent link="right_plam_2" />
    <child link="right_plam_3" />
    <axis xyz="0 0 0" />
  </joint>
  <link name="right_plam_force_sensor">
    <inertial>
      <origin xyz="0.00135015380328561 -0.00241176259562209 -0.00177409297911233" rpy="0 0 0" />
      <mass value="0.00449423927061171" />
      <inertia ixx="2.77343347350042E-07" ixy="-5.59517451189968E-13" ixz="2.86825536833881E-13" iyy="1.25942537762186E-06" iyz="5.96429255234865E-09" izz="1.53055908452317E-06" />
    </inertial>
    <visual>
      <origin xyz="0 0 0" rpy="0 0 0" />
      <geometry>
        <mesh filename="meshes/right_plam_force_sensor.STL" />
      </geometry>
      <material name="">
        <color rgba="0.298039215686275 0.298039215686275 0.298039215686275 1" />
      </material>
    </visual>
    <collision>
      <origin xyz="0 0 0" rpy="0 0 0" />
      <geometry>
        <mesh filename="meshes/right_plam_force_sensor.STL" />
      </geometry>
    </collision>
  </link>
  <joint name="right_plam_force_sensor_joint" type="fixed">
    <origin xyz="0.0159401947506102 -0.00135045394126701 0.0737460952299602" rpy="1.5707963267949 0 1.5707963267949" />
    <parent link="right_plam_2" />
    <child link="right_plam_force_sensor" />
    <axis xyz="0 0 0" />
  </joint>
  <link name="right_thumb_1">
    <inertial>
      <origin xyz="-0.00015 0.00544 -0.0048200000000000005" rpy="0 0 0" />
      <mass value="0.016800000000000002" />
      <inertia ixx="7.3387e-07" ixy="-1.436e-08" ixz="-1.11e-09" iyy="2.7925e-07" iyz="-3.296e-08" izz="5.8189e-07" />
    </inertial>
    <visual>
      <origin xyz="0 0 0" rpy="0 0 0" />
      <geometry>
        <mesh filename="meshes/right_thumb_1.STL" />
      </geometry>
      <material name="">
        <color rgba="1 1 1 1" />
      </material>
    </visual>
    <collision>
      <origin xyz="0 0 0" rpy="0 0 0" />
      <geometry>
        <mesh filename="meshes/right_thumb_1.STL" />
      </geometry>
    </collision>
  </link>

  <joint name="right_thumb_1_joint" type="revolute">
    <origin xyz="0.01836 0.027241 0.070511" rpy="0 0 0" />
    <parent link="right_base_link" />
    <child link="right_thumb_1" />
    <axis xyz="8.7274E-05 0 -1" />
    <limit lower="0" upper="2.0943951023931953" effort="1" velocity="2" />
  </joint>
  <link name="right_thumb_2">
    <inertial>
      <origin xyz="-0.0238 0.01042 0.00478" rpy="0 0 0" />
      <mass value="0.06526" />
      <inertia ixx="1.378224e-05" ixy="5.95663e-06" ixz="-1.9799999999999998e-09" iyy="1.1840129999999999e-05" iyz="7.070000000000001e-09" izz="2.249189e-05" />
    </inertial>
    <visual>
      <origin xyz="0 0 0" rpy="0 0 0" />
      <geometry>
        <mesh filename="meshes/right_thumb_2.STL" />
      </geometry>
      <material name="">
        <color rgba="0.25 0.25 0.25 1" />
      </material>
    </visual>
    <collision>
      <origin xyz="0 0 0" rpy="0 0 0" />
      <geometry>
        <mesh filename="meshes/right_thumb_2.STL" />
      </geometry>
    </collision>
  </link>
  <joint name="right_thumb_2_joint" type="revolute">
    <origin xyz="0.0047995 0.013396 -0.0052536" rpy="1.5707 0 -1.5708" />
    <parent link="right_thumb_1" />
    <child link="right_thumb_2" />
    <axis xyz="0 0 -1" />
    <limit lower="0" upper="0.4745550236172582" effort="1" velocity="2" />
  </joint>
  <link name="right_thumb_3">
    <inertial>
      <origin xyz="-0.01255 0.00331 0.00799" rpy="0 0 0" />
      <mass value="0.01333" />
      <inertia ixx="1.41987e-06" ixy="1.4979e-07" ixz="-6.3e-10" iyy="1.18482e-06" iyz="1.76e-09" izz="1.6920999999999999e-06" />
    </inertial>
    <visual>
      <origin xyz="0 0 0" rpy="0 0 0" />
      <geometry>
        <mesh filename="meshes/right_thumb_3.STL" />
      </geometry>
      <material name="">
        <color rgba="0.25 0.25 0.25 1" />
      </material>
    </visual>
    <collision>
      <origin xyz="0 0 0" rpy="0 0 0" />
      <geometry>
        <mesh filename="meshes/right_thumb_3.STL" />
      </geometry>
    </collision>
  </link>
  <joint name="right_thumb_3_joint" type="revolute">
    <origin xyz="-0.029155 0.03869 -0.0032" rpy="0 0 0" />
    <parent link="right_thumb_2" />
    <child link="right_thumb_3" />
    <axis xyz="0 0 -1" />
    <limit lower="0" upper="3.14" effort="1" velocity="2" />
      <mimic joint="right_thumb_2_joint" multiplier="1.2953" offset="0" />
  </joint>
  <link name="right_thumb_4">
    <inertial>
      <origin xyz="-0.010199999999999999 0.00886 0.0067" rpy="0 0 0" />
      <mass value="0.011439999999999999" />
      <inertia ixx="9.4221e-07" ixy="1.6288e-07" ixz="-0.0" iyy="3.9966e-07" iyz="-0.0" izz="9.478099999999999e-07" />
    </inertial>
    <visual>
      <origin xyz="0 0 0" rpy="0 0 0" />
      <geometry>
        <mesh filename="meshes/right_thumb_4.STL" />
      </geometry>
      <material name="">
        <color rgba="0.25 0.25 0.25 1" />
      </material>
    </visual>
    <collision>
      <origin xyz="0 0 0" rpy="0 0 0" />
      <geometry>
        <mesh filename="meshes/right_thumb_4.STL" />
      </geometry>
    </collision>
  </link>
  <joint name="right_thumb_4_joint" type="revolute">
    <origin xyz="-0.01441 0.014648 0.0013" rpy="0 0 0" />
    <parent link="right_thumb_3" />
    <child link="right_thumb_4" />
    <axis xyz="0 0 -1" />
    <limit lower="0" upper="3.14" effort="1" velocity="2" />
      <mimic joint="right_thumb_3_joint" multiplier="0.8962" offset="0" />
  </joint>
  <link name="right_thumb_tip">
    <visual>
      <origin
        xyz="0 0 0"
        rpy="0 0 0" />
      <geometry>
        <sphere radius="0.001"/>
      </geometry>
      <material name="green">
        <color rgba="0 1 0 1" />
      </material>
    </visual>
  </link>
  <joint name="right_thumb_tip_joint" type="fixed">
    <parent link="right_thumb_4"/>
    <child link="right_thumb_tip"/>
    <origin rpy="0 0 0" xyz="-0.014 0.025 0.0065"/>
  </joint>
  <link name="right_index_1">
    <inertial>
      <origin xyz="0.00046 0.01509 0.0060999999999999995" rpy="0 0 0" />
      <mass value="0.01111" />
      <inertia ixx="2.04599e-06" ixy="-3.703e-08" ixz="1.77e-09" iyy="5.4029e-07" iyz="9.149e-08" izz="2.0895e-06" />
    </inertial>
    <visual>
      <origin xyz="0 0 0" rpy="0 0 0" />
      <geometry>
        <mesh filename="meshes/right_index_1.STL" />
      </geometry>
      <material name="">
        <color rgba="0.25 0.25 0.25 1" />
      </material>
    </visual>
    <collision>
      <origin xyz="0 0 0" rpy="0 0 0" />
      <geometry>
        <mesh filename="meshes/right_index_1.STL" />
      </geometry>
    </collision>
  </link>
  <joint name="right_index_1_joint" type="revolute">
    <origin xyz="0.00070751 0.034376 0.13554" rpy="1.5097 0 0" />
    <parent link="right_base_link" />
    <child link="right_index_1" />
    <axis xyz="0 0 -1" />
    <limit lower="0" upper="1.5285593588966337" effort="1" velocity="2" />
  </joint>
  <link name="right_index_2">
    <inertial>
      <origin xyz="-0.00436 0.01623 0.005019999999999999" rpy="0 0 0" />
      <mass value="0.0103" />
      <inertia ixx="1.5669000000000002e-06" ixy="-2.2414e-07" ixz="1.3699999999999999e-08" iyy="2.9717e-07" iyz="7.84e-08" izz="1.5746300000000001e-06" />
    </inertial>
    <visual>
      <origin xyz="0 0 0" rpy="0 0 0" />
      <geometry>
        <mesh filename="meshes/right_index_2.STL" />
      </geometry>
      <material name="">
        <color rgba="0.25 0.25 0.25 1" />
      </material>
    </visual>
    <collision>
      <origin xyz="0 0 0" rpy="0 0 0" />
      <geometry>
        <mesh filename="meshes/right_index_2.STL" />
      </geometry>
    </collision>
  </link>
  <joint name="right_index_2_joint" type="revolute">
    <origin xyz="0.0031056 0.032854 0.001" rpy="0 0 0" />
    <parent link="right_index_1" />
    <child link="right_index_2" />
    <axis xyz="0 0 -1" />
    <limit lower="0" upper="3.14" effort="1" velocity="2" />
      <mimic joint="right_index_1_joint" multiplier="1.1545" offset="0" />
  </joint>
  <link name="right_index_tip">
    <visual>
      <origin
        xyz="0 0 0"
        rpy="0 0 0" />
      <geometry>
        <sphere radius="0.001"/>
      </geometry>
      <material name="green">
        <color rgba="0 1 0 1" />
      </material>
    </visual>
  </link>
  <joint name="right_index_tip_joint" type="fixed">
    <parent link="right_index_2"/>
    <child link="right_index_tip"/>
    <origin rpy="0 0 0" xyz="0.006 0.0365 0.006"/>
  </joint>

  <link name="right_middle_1">
    <inertial>
      <origin xyz="0.00046 0.01468 0.00701" rpy="0 0 0" />
      <mass value="0.01111" />
      <inertia ixx="2.04599e-06" ixy="-3.707e-08" ixz="-4.9e-10" iyy="5.3491e-07" iyz="-3.6e-09" izz="2.09487e-06" />
    </inertial>
    <visual>
      <origin xyz="0 0 0" rpy="0 0 0" />
      <geometry>
        <mesh filename="meshes/right_middle_1.STL" />
      </geometry>
      <material name="">
        <color rgba="0.25 0.25 0.25 1" />
      </material>
    </visual>
    <collision>
      <origin xyz="0 0 0" rpy="0 0 0" />
      <geometry>
        <mesh filename="meshes/right_middle_1.STL" />
      </geometry>
    </collision>
  </link>
  <joint name="right_middle_1_joint" type="revolute">
    <origin xyz="0.00070746 0.015767 0.13648" rpy="1.5708 0 0" />
    <parent link="right_base_link" />
    <child link="right_middle_1" />
    <axis xyz="0 0 -1" />
    <limit lower="0" upper="1.5285593588966337" effort="1" velocity="2" />
  </joint>
  <link name="right_middle_2">
    <inertial>
      <origin xyz="-0.004019999999999999 0.01731 0.006" rpy="0 0 0" />
      <mass value="0.01122" />
      <inertia ixx="1.92755e-06" ixy="-2.9305e-07" ixz="-1.0000000000000001e-11" iyy="3.2973000000000003e-07" iyz="-1.0000000000000001e-11" izz="1.95229e-06" />
    </inertial>
    <visual>
      <origin xyz="0 0 0" rpy="0 0 0" />
      <geometry>
        <mesh filename="meshes/right_middle_2.STL" />
      </geometry>
      <material name="">
        <color rgba="0.25 0.25 0.25 1" />
      </material>
    </visual>
    <collision>
      <origin xyz="0 0 0" rpy="0 0 0" />
      <geometry>
        <mesh filename="meshes/right_middle_2.STL" />
      </geometry>
    </collision>
  </link>
  <joint name="right_middle_2_joint" type="revolute">
    <origin xyz="0.0031056 0.032854 0.001" rpy="0 0 0" />
    <parent link="right_middle_1" />
    <child link="right_middle_2" />
    <axis xyz="0 0 -1" />
    <limit lower="0" upper="3.14" effort="1" velocity="2" />
      <mimic joint="right_middle_1_joint" multiplier="1.1545" offset="0" />
  </joint>
  <link name="right_middle_tip">
    <visual>
      <origin
        xyz="0 0 0"
        rpy="0 0 0" />
      <geometry>
        <sphere radius="0.001"/>
      </geometry>
      <material name="green">
        <color rgba="0 1 0 1" />
      </material>
    </visual>
  </link>
  <joint name="right_middle_tip_joint" type="fixed">
    <parent link="right_middle_2"/>
    <child link="right_middle_tip"/>
    <origin rpy="0 0 0" xyz="0.007 0.039 0.006"/>
  </joint>

  <link name="right_ring_1">
    <inertial>
      <origin xyz="0.00046 0.0143 0.00777" rpy="0 0 0" />
      <mass value="0.01111" />
      <inertia ixx="2.04599e-06" ixy="-3.699e-08" ixz="-2.43e-09" iyy="5.395599999999999e-07" iyz="-8.511e-08" izz="2.09023e-06" />
    </inertial>
    <visual>
      <origin xyz="0 0 0" rpy="0 0 0" />
      <geometry>
        <mesh filename="meshes/right_ring_1.STL" />
      </geometry>
      <material name="">
        <color rgba="0.25 0.25 0.25 1" />
      </material>
    </visual>
    <collision>
      <origin xyz="0 0 0" rpy="0 0 0" />
      <geometry>
        <mesh filename="meshes/right_ring_1.STL" />
      </geometry>
    </collision>
  </link>
  <joint name="right_ring_1_joint" type="revolute">
    <origin xyz="0.00070746 -0.0030876 0.13643" rpy="1.6232 0 0" />
    <parent link="right_base_link" />
    <child link="right_ring_1" />
    <axis xyz="0 0 -1" />
    <limit lower="0" upper="1.5285593588966337" effort="1" velocity="2" />
  </joint>
  <link name="right_ring_2">
    <inertial>
      <origin xyz="-0.00436 0.015560000000000001 0.0068200000000000005" rpy="0 0 0" />
      <mass value="0.0103" />
      <inertia ixx="1.5669000000000002e-06" ixy="-2.2425e-07" ixz="-1.1759999999999999e-08" iyy="2.959e-07" iyz="-6.729e-08" izz="1.5758900000000002e-06" />
    </inertial>
    <visual>
      <origin xyz="0 0 0" rpy="0 0 0" />
      <geometry>
        <mesh filename="meshes/right_ring_2.STL" />
      </geometry>
      <material name="">
        <color rgba="0.25 0.25 0.25 1" />
      </material>
    </visual>
    <collision>
      <origin xyz="0 0 0" rpy="0 0 0" />
      <geometry>
        <mesh filename="meshes/right_ring_2.STL" />
      </geometry>
    </collision>
  </link>
  <joint name="right_ring_2_joint" type="revolute">
    <origin xyz="0.0031056 0.032854 0.001" rpy="0 0 0" />
    <parent link="right_ring_1" />
    <child link="right_ring_2" />
    <axis xyz="0 0 -1" />
    <limit lower="0" upper="3.14" effort="1" velocity="2" />
      <mimic joint="right_ring_1_joint" multiplier="1.1545" offset="0" />
  </joint>
  <link name="right_ring_tip">
    <visual>
      <origin
        xyz="0 0 0"
        rpy="0 0 0" />
      <geometry>
        <sphere radius="0.001"/>
      </geometry>
      <material name="green">
        <color rgba="0 1 0 1" />
      </material>
    </visual>
  </link>
  <joint name="right_ring_tip_joint" type="fixed">
    <parent link="right_ring_2"/>
    <child link="right_ring_tip"/>
    <origin rpy="0 0 0" xyz="0.006 0.036 0.006"/>
  </joint>

  <link name="right_little_1">
    <inertial>
      <origin xyz="0.00046 0.013869999999999999 0.0085" rpy="0 0 0" />
      <mass value="0.01111" />
      <inertia ixx="2.04599e-06" ixy="-3.6810000000000003e-08" ixz="-4.360000000000001e-09" iyy="5.527e-07" iyz="-1.6568e-07" izz="2.07708e-06" />
    </inertial>
    <visual>
      <origin xyz="0 0 0" rpy="0 0 0" />
      <geometry>
        <mesh filename="meshes/right_little_1.STL" />
      </geometry>
      <material name="">
        <color rgba="0.25 0.25 0.25 1" />
      </material>
    </visual>
    <collision>
      <origin xyz="0 0 0" rpy="0 0 0" />
      <geometry>
        <mesh filename="meshes/right_little_1.STL" />
      </geometry>
    </collision>
  </link>
  <joint name="right_little_1_joint" type="revolute">
    <origin xyz="0.00070753 -0.021451 0.13527" rpy="1.6755 0 0" />
    <parent link="right_base_link" />
    <child link="right_little_1" />
    <axis xyz="0 0 -1" />
    <limit lower="0" upper="1.5285593588966337" effort="1" velocity="2" />
  </joint>
  <link name="right_little_2">
    <inertial>
      <origin xyz="-0.004070000000000001 0.01192 0.00728" rpy="0 0 0" />
      <mass value="0.00839" />
      <inertia ixx="9.3539e-07" ixy="-1.6843e-07" ixz="-1.7670000000000002e-08" iyy="2.4681e-07" iyz="-7.359e-08" izz="9.379400000000001e-07" />
    </inertial>
    <visual>
      <origin xyz="0 0 0" rpy="0 0 0" />
      <geometry>
        <mesh filename="meshes/right_little_2.STL" />
      </geometry>
      <material name="">
        <color rgba="0.25 0.25 0.25 1" />
      </material>
    </visual>
    <collision>
      <origin xyz="0 0 0" rpy="0 0 0" />
      <geometry>
        <mesh filename="meshes/right_little_2.STL" />
      </geometry>
    </collision>
  </link>
  <joint name="right_little_2_joint" type="revolute">
    <origin xyz="0.0031057 0.032854 0.001" rpy="0 0 0" />
    <parent link="right_little_1" />
    <child link="right_little_2" />
    <axis xyz="0 0 -1" />
    <limit lower="0" upper="3.14" effort="1" velocity="2" />
      <mimic joint="right_little_1_joint" multiplier="1.1545" offset="0" />
  </joint>
  <link name="right_little_tip">
    <visual>
      <origin
        xyz="0 0 0"
        rpy="0 0 0" />
      <geometry>
        <sphere radius="0.001"/>
      </geometry>
      <material name="green">
        <color rgba="0 1 0 1" />
      </material>
    </visual>
  </link>
  <joint name="right_little_tip_joint" type="fixed">
    <parent link="right_little_2"/>
    <child link="right_little_tip"/>
    <origin rpy="0 0 0" xyz="0.006 0.029 0.006"/>
  </joint>

  </robot>